Workbook

Sheet Обновлённые данные
J1: Лекции | K1: Практ. | L1: Лаб.р. | M1: конс. | N1: экз | O1: диф.зач | P1: зач | Q1: курсов.р | R1: ГЭК (защита) | S1: ГЭК (экзамен) | T1: Контроль | U1: Практики | V1: Рук-во | AC1: учебный год | AD1: 2015/2016 | AH1: 2016/2017 | AL1: 2017/2018 | AP1: 2018/2019 | AT1: 2019/2020 | AX1: 2020/2021 | BB1: 2021/2022 | BG1: Стандарт часов по должностям | BJ1: Абдуллаева Любовь Магомедовна | BK1: Абрамян Геннадий Владимирович | BL1: Авксентьева Елена Юрьевна | BM1: Акимов Станислав Сергеевич | BN1: Аксютин Павел Александрович | BO1: Атаян Ануш Михайловна | BP1: Байгузева Александра Петровна | BQ1: Барченко Сергей Алексеевич | BR1: Бендюкова Татьяна Савельевна | BS1: Богатова Елена Владимировна | BT1: Бочковская Виктория Леонидовна | BU1: Васильев Сергей Васильевич | BV1: Василькова Ирина Генриховна | BW1: Васютина Ирина Павловна | BX1: Власов Дмитрий Викторович | BY1: Власова Елена Зотиковна | BZ1: Воробьев Владимир Иванович | CA1: Гасумянц Виталий Эдуардович | CB1: Гончарко Дмитрий Николаевич | CC1: Гончарова Светлана Викторовна | CD1: Государев Илья Борисович | CE1: Готская Ирина Борисовна | CF1: Дулин Юрий Николаевич | CG1: Еремина Нелли Владимировна | CH1: Ерошкина Ольга Николаевна | CI1: Есипова Александра Анатольевна | CJ1: Жаркой Александр Борисович | CK1: Жуков Николай Николаевич | CL1: Жукова Татьяна Викторовна | CM1: Земляницин Владимир Александрович | CN1: Зюкин Анатолий Васильевич | CO1: Иванов Георгий Владимирович | CP1: Иванова Екатерина Алексеевна | CQ1: Ильина Татьяна Сергеевна | CR1: Карпова Наталья Александровна | CS1: Качоровская Анна Евгеньевна | CT1: Колдунов Андрей Витальевич | CU1: Кондаков Юрий Евгеньевич | CV1: Копыльцов Александр Васильевич | CW1: Косова Ирина Святославна | CX1: Кравченко Наталия Николаевна | CY1: Кудрявцева Наталья Фаддеевна | CZ1: Кужельная Оксана Владимировна | DA1: Кузнецова Надежда Леонидовна | DB1: Лапина Ирина Александровна | DC1: Левина Ирина Николаевна | DD1: Лужков Александр Альбертович | DE1: Любимов Александр Владимирович | DF1: Маслов Вадим Владимирович | DG1: Матюшичев Илья Юрьевич | DH1: Михайлов Александр Борисович | DI1: Николаева Наталья Викторовна | DJ1: Пальтиель Лев Романович | DK1: Пантелеева Людмила Валентиновна | DL1: Певзнер Игорь Михайлович | DM1: Пентина Анна Юрьевна | DN1: Полякова Наталия Александровна | DO1: Порязь Надежда Вадимовна | DP1: Поспелов Михаил Владимирович | DQ1: Пую Юлия Валерьевна | DR1: Разуваев Николай Викторович | DS1: Райкова Вера Алексеевна | DT1: Рудаков Леонид Ильич | DU1: Серегин Александр Николаевич | DV1: Серегин Павел Павлович | DW1: Силантьев Евгений Евгеньевич | DX1: Смирнов Александр Михайлович | DY1: Тарамжина Людмила Витольдовна | DZ1: Тихонова Анастасия Михайловна | EA1: Хахалина Марина Сергеевна | EB1: Хинич Иосиф Исаакович | EC1: Шалденкова Анна Владимировна | ED1: Шангин Андрей Борисович | EE1: Швецкий Михаил Владимирович | EF1: Швинк Лоренс Ричард
BI2: =SUM(BJ2:EF2,,CS15) -> 43.713838 | BJ2: =SUM(BJ$3:BJ$880) -> 0.15560784 | BK2: =SUM(BK$3:BK$880) -> 2.4306493 | BL2: =SUM(BL$3:BL$880) -> 2.587418 | BM2: =SUM(BM$3:BM$880) -> 0.11064286 | BN2: =SUM(BN$3:BN$880) -> 1.0384889 | BO2: =SUM(BO$3:BO$880) -> 1.3800113 | BP2: =SUM(BP$3:BP$880) -> 0.07675 | BQ2: =SUM(BQ$3:BQ$880) -> 0.054666667 | ... EH2: =SUM(EH$3:EH$880) -> 0
A3: Код УП | B3: Год нагрузки | C3: Кафедра | D3: ФИО | E3: Степень | F3: Должность | G3: Ставка | H3: Код РУП | I3: Дисциплина / практика / ВКР / ГИА | J3: Часы | W3: Студ. | X3: Количество групп | Y3: Количество подгрупп | Z3: Специальность | AA3: Вид нагрузки | AC3: курс | AD3: 1 | AE3: 2 | AF3: 3 | AG3: 4 | AH3: 1 | AI3: 2 | AJ3: 3 | AK3: 4 | AL3: 1 | AM3: 2 | AN3: 3 | AO3: 4 | AP3: 1 | AQ3: 2 | AR3: 3 | AS3: 4 | AT3: 1 | AU3: 2 | AV3: 3 | AW3: 4 | AX3: 1 | AY3: 2 | AZ3: 3 | BA3: 4 | BB3: 1 | BC3: 2 | BD3: 3 | BE3: 4 | BG3: Должность | BH3: Часы | BJ3: =IF(BJ$1=$D5,'Данные, контроль'!$AF4,0) -> 0 | BK3: =IF(BK$1=$D5,'Данные, контроль'!$AF4,0) -> 0.2366625 | BL3: =IF(BL$1=$D5,'Данные, контроль'!$AF4,0) -> 0 | BM3: =IF(BM$1=$D5,'Данные, контроль'!$AF4,0) -> 0 | BN3: =IF(BN$1=$D5,'Данные, контроль'!$AF4,0) -> 0 | BO3: =IF(BO$1=$D5,'Данные, контроль'!$AF4,0) -> 0 | BP3: =IF(BP$1=$D5,'Данные, контроль'!$AF4,0) -> 0 | BQ3: =IF(BQ$1=$D5,'Данные, контроль'!$AF4,0) -> 0 | ... EH3: =IF(EH$1=$D5,'Данные, контроль'!$AF4,0) -> 0
A4: 3250 | B4: 2015 | C4: компьютерных технологий и электронного обучения | D4: Абдуллаева Любовь Магомедовна | E4: кандидат педагогических наук | F4: доцент | G4: 1 | H4: 13809 | I4: Информатика | J4: =[1]Данные!J3 -> 34 | K4: =[1]Данные!K3 -> 0 | L4: =[1]Данные!L3 -> 102 | M4: =(J4 + K4 + L4)*0.1 -> 13.6 | N4: =2+(0.33*W4) -> 12.23 | O4: =0.25*W4 -> 7.75 | P4: =0.25*W4 -> 7.75 | Q4: =[1]Данные!Q3 -> 0 | R4: =[1]Данные!R3 -> 0 | S4: =[1]Данные!S3 -> 0 | T4: =[1]Данные!T3 -> 12 | U4: =[1]Данные!U3 -> 0 | V4: =[1]Данные!V3 -> 0 | W4: =[1]Данные!W3 -> 31 | X4: =[1]Данные!X3 -> 2 | ... Z4: =[1]Данные!Z3 -> 0 | AA4: осн | AC4: год поступления | AD4: 2015 | AE4: 2014 | AF4: 2013 | AG4: 2012 | AH4: 2016 | AI4: 2015 | AJ4: 2014 | AK4: 2013 | AL4: 2017 | AM4: 2016 | AN4: 2015 | AO4: 2014 | AP4: 2018 | AQ4: 2017 | AR4: 2016 | AS4: 2015 | AT4: 2019 | AU4: 2018 | AV4: 2017 | AW4: 2016 | AX4: 2020 | AY4: 2019 | AZ4: 2018 | BA4: 2017 | BB4: 2021 | BC4: 2020 | BD4: 2019 | BE4: 2018 | BG4: заведующий кафедрой | BH4: 700 | BJ4: =IF(BJ$1=$D6,'Данные, контроль'!$AF5,0) -> 0 | BK4: =IF(BK$1=$D6,'Данные, контроль'!$AF5,0) -> 0 | BL4: =IF(BL$1=$D6,'Данные, контроль'!$AF5,0) -> 0.13626667 | BM4: =IF(BM$1=$D6,'Данные, контроль'!$AF5,0) -> 0 | BN4: =IF(BN$1=$D6,'Данные, контроль'!$AF5,0) -> 0 | BO4: =IF(BO$1=$D6,'Данные, контроль'!$AF5,0) -> 0 | BP4: =IF(BP$1=$D6,'Данные, контроль'!$AF5,0) -> 0 | BQ4: =IF(BQ$1=$D6,'Данные, контроль'!$AF5,0) -> 0 | ... EH4: =IF(EH$1=$D6,'Данные, контроль'!$AF5,0) -> 0
A5: 4276 | B5: 2015 | C5: компьютерных технологий и электронного обучения | D5: Абрамян Геннадий Владимирович | E5: доктор педагогических наук | F5: профессор | G5: 1 | H5: 13818 | I5: Информационное обеспечение технологического образования. Применение Интернет-технологий в технологическом образовании | J5: =[1]Данные!J4 -> 18 | K5: =[1]Данные!K4 -> 0 | L5: =[1]Данные!L4 -> 54 | M5: =(J5 + K5 + L5)*0.1 -> 7.2 | N5: =2+(0.33*W5) -> 2 | O5: =0.25*W5 -> 0 | P5: =0.25*W5 -> 0 | Q5: =[1]Данные!Q4 -> 0 | R5: =[1]Данные!R4 -> 0 | S5: =[1]Данные!S4 -> 0 | T5: =[1]Данные!T4 -> 21 | U5: =[1]Данные!U4 -> 0 | V5: =[1]Данные!V4 -> 0 | W5: =[1]Данные!W4 -> 0 | X5: =[1]Данные!X4 -> 0 | ... Z5: =[1]Данные!Z4 -> 0 | AA5: осн | AC5: Бакалавры (ИВТ) | AD5: =[1]Данные!AD4 -> 14014 | AE5: =[1]Данные!AE4 -> 52346 | AF5: =[1]Данные!AF4 -> 8775 | AG5: =[1]Данные!AG4 -> 37233 | AH5: =[1]Данные!AH4 -> 15177 | AI5: =[1]Данные!AI4 -> 13809 | AJ5: =[1]Данные!AJ4 -> 25386 | AK5: =[1]Данные!AK4 -> 27453 | ... BE5: =[1]Данные!BE4 -> 4 курс 2018 год/пост | BG5: профессор | BH5: 750 | BJ5: =IF(BJ$1=$D7,'Данные, контроль'!$AF6,0) -> 0 | BK5: =IF(BK$1=$D7,'Данные, контроль'!$AF6,0) -> 0 | BL5: =IF(BL$1=$D7,'Данные, контроль'!$AF6,0) -> 0 | BM5: =IF(BM$1=$D7,'Данные, контроль'!$AF6,0) -> 0 | BN5: =IF(BN$1=$D7,'Данные, контроль'!$AF6,0) -> 0 | BO5: =IF(BO$1=$D7,'Данные, контроль'!$AF6,0) -> 0 | BP5: =IF(BP$1=$D7,'Данные, контроль'!$AF6,0) -> 0 | BQ5: =IF(BQ$1=$D7,'Данные, контроль'!$AF6,0) -> 0 | ... EH5: =IF(EH$1=$D7,'Данные, контроль'!$AF6,0) -> 0
A6: 4276 | B6: 2015 | C6: компьютерных технологий и электронного обучения | D6: Авксентьева Елена Юрьевна | E6: кандидат педагогических наук | F6: доцент | G6: 1 | H6: 13818 | I6: Информационные технологии | J6: =[1]Данные!J5 -> 0 | K6: =[1]Данные!K5 -> 0 | L6: =[1]Данные!L5 -> 0 | M6: =(J6 + K6 + L6)*0.1 -> 0 | N6: =2+(0.33*W6) -> 6.29 | O6: =0.25*W6 -> 3.25 | P6: =0.25*W6 -> 3.25 | Q6: =[1]Данные!Q5 -> 0 | R6: =[1]Данные!R5 -> 0 | S6: =[1]Данные!S5 -> 0 | T6: =[1]Данные!T5 -> 15 | U6: =[1]Данные!U5 -> 0 | V6: =[1]Данные!V5 -> 0 | W6: =[1]Данные!W5 -> 13 | X6: =[1]Данные!X5 -> 2 | ... Z6: =[1]Данные!Z5 -> 0 | AA6: осн | AC6: Магистры (КЭО) | AD6: =[1]Данные!AD5 -> 86354 | AE6: =[1]Данные!AE5 -> 80249 | AF6: =[1]Данные!AF5 -> 1 | AG6: =[1]Данные!AG5 -> 1 | AH6: =[1]Данные!AH5 -> 19404 | AI6: =[1]Данные!AI5 -> 19403 | AJ6: =[1]Данные!AJ5 -> 1 | AK6: =[1]Данные!AK5 -> 1 | ... BE6: =[1]Данные!BE5 -> 0 | BG6: доцент | BH6: 800 | BJ6: =IF(BJ$1=$D8,'Данные, контроль'!$AF7,0) -> 0 | BK6: =IF(BK$1=$D8,'Данные, контроль'!$AF7,0) -> 0 | BL6: =IF(BL$1=$D8,'Данные, контроль'!$AF7,0) -> 0 | BM6: =IF(BM$1=$D8,'Данные, контроль'!$AF7,0) -> 0 | BN6: =IF(BN$1=$D8,'Данные, контроль'!$AF7,0) -> 0 | BO6: =IF(BO$1=$D8,'Данные, контроль'!$AF7,0) -> 0 | BP6: =IF(BP$1=$D8,'Данные, контроль'!$AF7,0) -> 0 | BQ6: =IF(BQ$1=$D8,'Данные, контроль'!$AF7,0) -> 0 | ... EH6: =IF(EH$1=$D8,'Данные, контроль'!$AF7,0) -> 0
A7: 4276 | B7: 2015 | C7: компьютерных технологий и электронного обучения | D7: Гончарова Светлана Викторовна | E7: кандидат педагогических наук | F7: доцент | G7: 1 | H7: 13818 | I7: Информационные технологии | J7: =[1]Данные!J6 -> 9 | K7: =[1]Данные!K6 -> 32 | L7: =[1]Данные!L6 -> 0 | M7: =(J7 + K7 + L7)*0.1 -> 4.1 | N7: =2+(0.33*W7) -> 6.29 | O7: =0.25*W7 -> 3.25 | P7: =0.25*W7 -> 3.25 | Q7: =[1]Данные!Q6 -> 0 | R7: =[1]Данные!R6 -> 0 | S7: =[1]Данные!S6 -> 0 | T7: =[1]Данные!T6 -> 3 | U7: =[1]Данные!U6 -> 0 | V7: =[1]Данные!V6 -> 0 | W7: =[1]Данные!W6 -> 13 | X7: =[1]Данные!X6 -> 2 | ... Z7: =[1]Данные!Z6 -> 0 | AA7: осн | BG7: старший преподаватель | BH7: 850 | BJ7: =IF(BJ$1=$D9,'Данные, контроль'!$AF8,0) -> 0 | BK7: =IF(BK$1=$D9,'Данные, контроль'!$AF8,0) -> 0 | BL7: =IF(BL$1=$D9,'Данные, контроль'!$AF8,0) -> 0 | BM7: =IF(BM$1=$D9,'Данные, контроль'!$AF8,0) -> 0 | BN7: =IF(BN$1=$D9,'Данные, контроль'!$AF8,0) -> 0 | BO7: =IF(BO$1=$D9,'Данные, контроль'!$AF8,0) -> 0 | BP7: =IF(BP$1=$D9,'Данные, контроль'!$AF8,0) -> 0 | BQ7: =IF(BQ$1=$D9,'Данные, контроль'!$AF8,0) -> 0 | ... EH7: =IF(EH$1=$D9,'Данные, контроль'!$AF8,0) -> 0
A8: 4276 | B8: 2015 | C8: компьютерных технологий и электронного обучения | D8: Ильина Татьяна Сергеевна | E8: нет | F8: старший преподаватель | G8: 1 | H8: 13818 | I8: Информационные технологии | J8: =[1]Данные!J7 -> 0 | K8: =[1]Данные!K7 -> 64 | L8: =[1]Данные!L7 -> 0 | M8: =(J8 + K8 + L8)*0.1 -> 6.4 | N8: =2+(0.33*W8) -> 2 | O8: =0.25*W8 -> 0 | P8: =0.25*W8 -> 0 | Q8: =[1]Данные!Q7 -> 0 | R8: =[1]Данные!R7 -> 0 | S8: =[1]Данные!S7 -> 0 | T8: =[1]Данные!T7 -> 3 | U8: =[1]Данные!U7 -> 0 | V8: =[1]Данные!V7 -> 0 | W8: =[1]Данные!W7 -> 0 | X8: =[1]Данные!X7 -> 0 | ... Z8: =[1]Данные!Z7 -> 0 | AA8: осн | BG8: ассистент | BH8: 900 | BJ8: =IF(BJ$1=$D10,'Данные, контроль'!$AF9,0) -> 0 | BK8: =IF(BK$1=$D10,'Данные, контроль'!$AF9,0) -> 0 | BL8: =IF(BL$1=$D10,'Данные, контроль'!$AF9,0) -> 0 | BM8: =IF(BM$1=$D10,'Данные, контроль'!$AF9,0) -> 0 | BN8: =IF(BN$1=$D10,'Данные, контроль'!$AF9,0) -> 0 | BO8: =IF(BO$1=$D10,'Данные, контроль'!$AF9,0) -> 0 | BP8: =IF(BP$1=$D10,'Данные, контроль'!$AF9,0) -> 0 | BQ8: =IF(BQ$1=$D10,'Данные, контроль'!$AF9,0) -> 0 | ... EH8: =IF(EH$1=$D10,'Данные, контроль'!$AF9,0) -> 0
A9: 4276 | B9: 2016 | C9: компьютерных технологий и электронного обучения | D9: Готская Ирина Борисовна | E9: доктор педагогических наук | F9: профессор | G9: 1 | H9: 14784 | I9: Информационное обеспечение технологического образования. Применение электронных образовательных ресурсов в технологическом образовании | J9: =[1]Данные!J8 -> 32 | K9: =[1]Данные!K8 -> 0 | L9: =[1]Данные!L8 -> 120 | M9: =(J9 + K9 + L9)*0.1 -> 15.2 | N9: =2+(0.33*W9) -> 2 | O9: =0.25*W9 -> 0 | P9: =0.25*W9 -> 0 | Q9: =[1]Данные!Q8 -> 0 | R9: =[1]Данные!R8 -> 0 | S9: =[1]Данные!S8 -> 0 | T9: =[1]Данные!T8 -> 21 | U9: =[1]Данные!U8 -> 0 | V9: =[1]Данные!V8 -> 0 | W9: =[1]Данные!W8 -> 0 | X9: =[1]Данные!X8 -> 0 | ... Z9: =[1]Данные!Z8 -> 0 | AA9: осн | AC9: учебный год | AD9: 2015/2016 | AH9: 2016/2017 | AL9: 2017/2018 | AP9: 2018/2019 | AT9: 2019/2020 | AX9: 2020/2021 | BB9: 2021/2022 | BG9: эксперт-программист | BH9: 900 | BJ9: =IF(BJ$1=$D11,'Данные, контроль'!$AF10,0) -> 0 | BK9: =IF(BK$1=$D11,'Данные, контроль'!$AF10,0) -> 0.1288 | BL9: =IF(BL$1=$D11,'Данные, контроль'!$AF10,0) -> 0 | BM9: =IF(BM$1=$D11,'Данные, контроль'!$AF10,0) -> 0 | BN9: =IF(BN$1=$D11,'Данные, контроль'!$AF10,0) -> 0 | BO9: =IF(BO$1=$D11,'Данные, контроль'!$AF10,0) -> 0 | BP9: =IF(BP$1=$D11,'Данные, контроль'!$AF10,0) -> 0 | BQ9: =IF(BQ$1=$D11,'Данные, контроль'!$AF10,0) -> 0 | ... EH9: =IF(EH$1=$D11,'Данные, контроль'!$AF10,0) -> 0
A10: 4276 | B10: 2017 | C10: компьютерных технологий и электронного обучения | D10: Готская Ирина Борисовна | E10: доктор педагогических наук | F10: профессор | G10: 1 | H10: 16006 | I10: Информационное обеспечение технологического образования. Информационное обеспечение инновационной технологической деятельности | J10: =[1]Данные!J9 -> 16 | K10: =[1]Данные!K9 -> 0 | L10: =[1]Данные!L9 -> 60 | M10: =(J10 + K10 + L10)*0.1 -> 7.6 | N10: =2+(0.33*W10) -> 2 | O10: =0.25*W10 -> 0 | P10: =0.25*W10 -> 0 | Q10: =[1]Данные!Q9 -> 0 | R10: =[1]Данные!R9 -> 0 | S10: =[1]Данные!S9 -> 0 | T10: =[1]Данные!T9 -> 11 | U10: =[1]Данные!U9 -> 0 | V10: =[1]Данные!V9 -> 0 | W10: =[1]Данные!W9 -> 0 | X10: =[1]Данные!X9 -> 0 | ... Z10: =[1]Данные!Z9 -> 0 | AA10: осн | AC10: курс | AD10: 1 | AE10: 2 | AF10: 3 | AG10: 4 | AH10: 1 | AI10: 2 | AJ10: 3 | AK10: 4 | AL10: 1 | AM10: 2 | AN10: 3 | AO10: 4 | AP10: 1 | AQ10: 2 | AR10: 3 | AS10: 4 | AT10: 1 | AU10: 2 | AV10: 3 | AW10: 4 | AX10: 1 | AY10: 2 | AZ10: 3 | BA10: 4 | BB10: 1 | BC10: 2 | BD10: 3 | BE10: 4 | BG10: и.о.доцент | BH10: 900 | BJ10: =IF(BJ$1=$D12,'Данные, контроль'!$AF11,0) -> 0 | BK10: =IF(BK$1=$D12,'Данные, контроль'!$AF11,0) -> 0.12293333 | BL10: =IF(BL$1=$D12,'Данные, контроль'!$AF11,0) -> 0 | BM10: =IF(BM$1=$D12,'Данные, контроль'!$AF11,0) -> 0 | BN10: =IF(BN$1=$D12,'Данные, контроль'!$AF11,0) -> 0 | BO10: =IF(BO$1=$D12,'Данные, контроль'!$AF11,0) -> 0 | BP10: =IF(BP$1=$D12,'Данные, контроль'!$AF11,0) -> 0 | BQ10: =IF(BQ$1=$D12,'Данные, контроль'!$AF11,0) -> 0 | ... EH10: =IF(EH$1=$D12,'Данные, контроль'!$AF11,0) -> 0
A11: 4277 | B11: 2017 | C11: компьютерных технологий и электронного обучения | D11: Абрамян Геннадий Владимирович | E11: доктор педагогических наук | F11: профессор | G11: 1 | H11: 16005 | I11: Мультимедиа технологии и компьютерная графика | J11: =[1]Данные!J10 -> 18 | K11: =[1]Данные!K10 -> 0 | L11: =[1]Данные!L10 -> 54 | M11: =(J11 + K11 + L11)*0.1 -> 7.2 | N11: =2+(0.33*W11) -> 2 | O11: =0.25*W11 -> 0 | P11: =0.25*W11 -> 0 | Q11: =[1]Данные!Q10 -> 0 | R11: =[1]Данные!R10 -> 0 | S11: =[1]Данные!S10 -> 0 | T11: =[1]Данные!T10 -> 11 | U11: =[1]Данные!U10 -> 0 | V11: =[1]Данные!V10 -> 0 | W11: =[1]Данные!W10 -> 0 | X11: =[1]Данные!X10 -> 0 | ... Z11: =[1]Данные!Z10 -> 0 | AA11: осн | AC11: год поступления | AD11: 2015 | AE11: 2014 | AF11: 2013 | AG11: 2012 | AH11: 2016 | AI11: 2015 | AJ11: 2014 | AK11: 2013 | AL11: 2017 | AM11: 2016 | AN11: 2015 | AO11: 2014 | AP11: 2018 | AQ11: 2017 | AR11: 2016 | AS11: 2015 | AT11: 2019 | AU11: 2018 | AV11: 2017 | AW11: 2016 | AX11: 2020 | AY11: 2019 | AZ11: 2018 | BA11: 2017 | BB11: 2021 | BC11: 2020 | BD11: 2019 | BE11: 2018 | BG11: внешний | BH11: 900 | BJ11: =IF(BJ$1=$D13,'Данные, контроль'!$AF12,0) -> 0 | BK11: =IF(BK$1=$D13,'Данные, контроль'!$AF12,0) -> 0 | BL11: =IF(BL$1=$D13,'Данные, контроль'!$AF12,0) -> 0 | BM11: =IF(BM$1=$D13,'Данные, контроль'!$AF12,0) -> 0 | BN11: =IF(BN$1=$D13,'Данные, контроль'!$AF12,0) -> 0 | BO11: =IF(BO$1=$D13,'Данные, контроль'!$AF12,0) -> 0 | BP11: =IF(BP$1=$D13,'Данные, контроль'!$AF12,0) -> 0 | BQ11: =IF(BQ$1=$D13,'Данные, контроль'!$AF12,0) -> 0 | ... EH11: =IF(EH$1=$D13,'Данные, контроль'!$AF12,0) -> 0
A12: 4277 | B12: 2018 | C12: компьютерных технологий и электронного обучения | D12: Абрамян Геннадий Владимирович | E12: доктор педагогических наук | F12: профессор | G12: 1 | H12: 17336 | I12: Мультимедиа технологии и компьютерная графика | J12: =[1]Данные!J11 -> 0 | K12: =[1]Данные!K11 -> 0 | L12: =[1]Данные!L11 -> 36 | M12: =(J12 + K12 + L12)*0.1 -> 3.6 | N12: =2+(0.33*W12) -> 2 | O12: =0.25*W12 -> 0 | P12: =0.25*W12 -> 0 | Q12: =[1]Данные!Q11 -> 0 | R12: =[1]Данные!R11 -> 0 | S12: =[1]Данные!S11 -> 0 | T12: =[1]Данные!T11 -> 11 | U12: =[1]Данные!U11 -> 0 | V12: =[1]Данные!V11 -> 0 | W12: =[1]Данные!W11 -> 0 | X12: =[1]Данные!X11 -> 0 | ... Z12: =[1]Данные!Z11 -> 0 | AA12: осн | AC12: Бакалавры (ИВТ) | AD12: =[1]Данные!AD11 -> 13 | AE12: =[1]Данные!AE11 -> 15 | AF12: =[1]Данные!AF11 -> 34 | AG12: =[1]Данные!AG11 -> 54 | AH12: =[1]Данные!AH11 -> 27 | AI12: =[1]Данные!AI11 -> 31 | AJ12: =[1]Данные!AJ11 -> 12 | AK12: =[1]Данные!AK11 -> 23 | ... BE12: =[1]Данные!BE11 -> 39 | BG12: должность | BH12: 1 | BJ12: =IF(BJ$1=$D14,'Данные, контроль'!$AF13,0) -> 0 | BK12: =IF(BK$1=$D14,'Данные, контроль'!$AF13,0) -> 0.066375 | BL12: =IF(BL$1=$D14,'Данные, контроль'!$AF13,0) -> 0 | BM12: =IF(BM$1=$D14,'Данные, контроль'!$AF13,0) -> 0 | BN12: =IF(BN$1=$D14,'Данные, контроль'!$AF13,0) -> 0 | BO12: =IF(BO$1=$D14,'Данные, контроль'!$AF13,0) -> 0 | BP12: =IF(BP$1=$D14,'Данные, контроль'!$AF13,0) -> 0 | BQ12: =IF(BQ$1=$D14,'Данные, контроль'!$AF13,0) -> 0 | ... EH12: =IF(EH$1=$D14,'Данные, контроль'!$AF13,0) -> 0
A13: 4699 | B13: 2016 | C13: компьютерных технологий и электронного обучения | D13: Полякова Наталия Александровна | E13: кандидат педагогических наук | F13: доцент | G13: 1 | H13: 15014 | I13: Информационные технологии | J13: =[1]Данные!J12 -> 9 | K13: =[1]Данные!K12 -> 32 | L13: =[1]Данные!L12 -> 0 | M13: =(J13 + K13 + L13)*0.1 -> 4.1 | N13: =2+(0.33*W13) -> 2 | O13: =0.25*W13 -> 0 | P13: =0.25*W13 -> 0 | Q13: =[1]Данные!Q12 -> 0 | R13: =[1]Данные!R12 -> 0 | S13: =[1]Данные!S12 -> 0 | T13: =[1]Данные!T12 -> 6 | U13: =[1]Данные!U12 -> 0 | V13: =[1]Данные!V12 -> 0 | W13: =[1]Данные!W12 -> 0 | X13: =[1]Данные!X12 -> 0 | ... Z13: =[1]Данные!Z12 -> 0 | AA13: осн | AC13: Магистры (КЭО) | AD13: =[1]Данные!AD12 -> 11 | AE13: =[1]Данные!AE12 -> 60 | AF13: =[1]Данные!AF12 -> 0 | AG13: =[1]Данные!AG12 -> 0 | AH13: =[1]Данные!AH12 -> 12 | AI13: =[1]Данные!AI12 -> 42 | AJ13: =[1]Данные!AJ12 -> 0 | AK13: =[1]Данные!AK12 -> 0 | ... BE13: =[1]Данные!BE12 -> 0 | BG13: должность | BH13: 1 | BJ13: =IF(BJ$1=$D15,'Данные, контроль'!$AF14,0) -> 0 | BK13: =IF(BK$1=$D15,'Данные, контроль'!$AF14,0) -> 0 | BL13: =IF(BL$1=$D15,'Данные, контроль'!$AF14,0) -> 0 | BM13: =IF(BM$1=$D15,'Данные, контроль'!$AF14,0) -> 0 | BN13: =IF(BN$1=$D15,'Данные, контроль'!$AF14,0) -> 0.1216 | BO13: =IF(BO$1=$D15,'Данные, контроль'!$AF14,0) -> 0 | BP13: =IF(BP$1=$D15,'Данные, контроль'!$AF14,0) -> 0 | BQ13: =IF(BQ$1=$D15,'Данные, контроль'!$AF14,0) -> 0 | ... EH13: =IF(EH$1=$D15,'Данные, контроль'!$AF14,0) -> 0
A14: 4699 | B14: 2018 | C14: компьютерных технологий и электронного обучения | D14: Абрамян Геннадий Владимирович | E14: доктор педагогических наук | F14: профессор | G14: 1 | H14: 17337 | I14: Мультимедиа технологии и компьютерная графика | J14: =[1]Данные!J13 -> 18 | K14: =[1]Данные!K13 -> 0 | L14: =[1]Данные!L13 -> 54 | M14: =(J14 + K14 + L14)*0.1 -> 7.2 | N14: =2+(0.33*W14) -> 2 | O14: =0.25*W14 -> 0 | P14: =0.25*W14 -> 0 | Q14: =[1]Данные!Q13 -> 0 | R14: =[1]Данные!R13 -> 0 | S14: =[1]Данные!S13 -> 0 | T14: =[1]Данные!T13 -> 10 | U14: =[1]Данные!U13 -> 0 | V14: =[1]Данные!V13 -> 0 | W14: =[1]Данные!W13 -> 0 | X14: =[1]Данные!X13 -> 0 | ... Z14: =[1]Данные!Z13 -> 0 | AA14: осн | BG14: должность | BH14: 1 | BJ14: =IF(BJ$1=$D16,'Данные, контроль'!$AF15,0) -> 0 | BK14: =IF(BK$1=$D16,'Данные, контроль'!$AF15,0) -> 0 | BL14: =IF(BL$1=$D16,'Данные, контроль'!$AF15,0) -> 0 | BM14: =IF(BM$1=$D16,'Данные, контроль'!$AF15,0) -> 0 | BN14: =IF(BN$1=$D16,'Данные, контроль'!$AF15,0) -> 0 | BO14: =IF(BO$1=$D16,'Данные, контроль'!$AF15,0) -> 0 | BP14: =IF(BP$1=$D16,'Данные, контроль'!$AF15,0) -> 0 | BQ14: =IF(BQ$1=$D16,'Данные, контроль'!$AF15,0) -> 0 | ... EH14: =IF(EH$1=$D16,'Данные, контроль'!$AF15,0) -> 0
A15: 4701 | B15: 2016 | C15: компьютерных технологий и электронного обучения | D15: Аксютин Павел Александрович | E15: нет | F15: ассистент | G15: 0.5 | H15: 15313 | I15: Информационные технологии | J15: =[1]Данные!J14 -> 0 | K15: =[1]Данные!K14 -> 0 | L15: =[1]Данные!L14 -> 0 | M15: =(J15 + K15 + L15)*0.1 -> 0 | N15: =2+(0.33*W15) -> 2 | O15: =0.25*W15 -> 0 | P15: =0.25*W15 -> 0 | Q15: =[1]Данные!Q14 -> 0 | R15: =[1]Данные!R14 -> 0 | S15: =[1]Данные!S14 -> 0 | T15: =[1]Данные!T14 -> 7 | U15: =[1]Данные!U14 -> 0 | V15: =[1]Данные!V14 -> 0 | W15: =[1]Данные!W14 -> 0 | X15: =[1]Данные!X14 -> 0 | ... Z15: =[1]Данные!Z14 -> 0 | AA15: осн | BG15: должность | BH15: 1 | BJ15: =IF(BJ$1=$D17,'Данные, контроль'!$AF16,0) -> 0 | BK15: =IF(BK$1=$D17,'Данные, контроль'!$AF16,0) -> 0 | BL15: =IF(BL$1=$D17,'Данные, контроль'!$AF16,0) -> 0 | BM15: =IF(BM$1=$D17,'Данные, контроль'!$AF16,0) -> 0 | BN15: =IF(BN$1=$D17,'Данные, контроль'!$AF16,0) -> 0 | BO15: =IF(BO$1=$D17,'Данные, контроль'!$AF16,0) -> 0 | BP15: =IF(BP$1=$D17,'Данные, контроль'!$AF16,0) -> 0 | BQ15: =IF(BQ$1=$D17,'Данные, контроль'!$AF16,0) -> 0 | ... EH15: =IF(EH$1=$D17,'Данные, контроль'!$AF16,0) -> 0
A16: 4701 | B16: 2016 | C16: компьютерных технологий и электронного обучения | D16: Власова Елена Зотиковна | E16: доктор педагогических наук | F16: заведующий кафедрой | G16: 1 | H16: 15313 | I16: Информатика | J16: =[1]Данные!J15 -> 2 | K16: =[1]Данные!K15 -> 0 | L16: =[1]Данные!L15 -> 0 | M16: =(J16 + K16 + L16)*0.1 -> 0.2 | N16: =2+(0.33*W16) -> 2 | O16: =0.25*W16 -> 0 | P16: =0.25*W16 -> 0 | Q16: =[1]Данные!Q15 -> 0 | R16: =[1]Данные!R15 -> 0 | S16: =[1]Данные!S15 -> 0 | T16: =[1]Данные!T15 -> 9 | U16: =[1]Данные!U15 -> 0 | V16: =[1]Данные!V15 -> 0 | W16: =[1]Данные!W15 -> 0 | X16: =[1]Данные!X15 -> 0 | ... Z16: =[1]Данные!Z15 -> 0 | AA16: осн | BG16: должность | BH16: 1 | BJ16: =IF(BJ$1=$D18,'Данные, контроль'!$AF17,0) -> 0 | BK16: =IF(BK$1=$D18,'Данные, контроль'!$AF17,0) -> 0 | BL16: =IF(BL$1=$D18,'Данные, контроль'!$AF17,0) -> 0 | BM16: =IF(BM$1=$D18,'Данные, контроль'!$AF17,0) -> 0 | BN16: =IF(BN$1=$D18,'Данные, контроль'!$AF17,0) -> 0 | BO16: =IF(BO$1=$D18,'Данные, контроль'!$AF17,0) -> 0 | BP16: =IF(BP$1=$D18,'Данные, контроль'!$AF17,0) -> 0 | BQ16: =IF(BQ$1=$D18,'Данные, контроль'!$AF17,0) -> 0 | ... EH16: =IF(EH$1=$D18,'Данные, контроль'!$AF17,0) -> 0
A17: 4701 | B17: 2016 | C17: компьютерных технологий и электронного обучения | D17: Гончарова Светлана Викторовна | E17: кандидат педагогических наук | F17: доцент | G17: 1 | H17: 15313 | I17: Информатика | J17: =[1]Данные!J16 -> 32 | K17: =[1]Данные!K16 -> 0 | L17: =[1]Данные!L16 -> 51 | M17: =(J17 + K17 + L17)*0.1 -> 8.3 | N17: =2+(0.33*W17) -> 2 | O17: =0.25*W17 -> 0 | P17: =0.25*W17 -> 0 | Q17: =[1]Данные!Q16 -> 0 | R17: =[1]Данные!R16 -> 0 | S17: =[1]Данные!S16 -> 0 | T17: =[1]Данные!T16 -> 4 | U17: =[1]Данные!U16 -> 0 | V17: =[1]Данные!V16 -> 0 | W17: =[1]Данные!W16 -> 0 | X17: =[1]Данные!X16 -> 0 | ... Z17: =[1]Данные!Z16 -> 0 | AA17: осн | BJ17: =IF(BJ$1=$D19,'Данные, контроль'!$AF18,0) -> 0 | BK17: =IF(BK$1=$D19,'Данные, контроль'!$AF18,0) -> 0 | BL17: =IF(BL$1=$D19,'Данные, контроль'!$AF18,0) -> 0 | BM17: =IF(BM$1=$D19,'Данные, контроль'!$AF18,0) -> 0 | BN17: =IF(BN$1=$D19,'Данные, контроль'!$AF18,0) -> 0 | BO17: =IF(BO$1=$D19,'Данные, контроль'!$AF18,0) -> 0 | BP17: =IF(BP$1=$D19,'Данные, контроль'!$AF18,0) -> 0 | BQ17: =IF(BQ$1=$D19,'Данные, контроль'!$AF18,0) -> 0 | ... EH17: =IF(EH$1=$D19,'Данные, контроль'!$AF18,0) -> 0
A18: 4701 | B18: 2016 | C18: компьютерных технологий и электронного обучения | D18: Ильина Татьяна Сергеевна | E18: нет | F18: старший преподаватель | G18: 1 | H18: 15313 | I18: Информатика | J18: =[1]Данные!J17 -> 0 | K18: =[1]Данные!K17 -> 0 | L18: =[1]Данные!L17 -> 102 | M18: =(J18 + K18 + L18)*0.1 -> 10.2 | N18: =2+(0.33*W18) -> 2 | O18: =0.25*W18 -> 0 | P18: =0.25*W18 -> 0 | Q18: =[1]Данные!Q17 -> 0 | R18: =[1]Данные!R17 -> 0 | S18: =[1]Данные!S17 -> 0 | T18: =[1]Данные!T17 -> 10 | U18: =[1]Данные!U17 -> 0 | V18: =[1]Данные!V17 -> 0 | W18: =[1]Данные!W17 -> 0 | X18: =[1]Данные!X17 -> 0 | ... Z18: =[1]Данные!Z17 -> 0 | AA18: осн | BJ18: =IF(BJ$1=$D20,'Данные, контроль'!$AF19,0) -> 0 | BK18: =IF(BK$1=$D20,'Данные, контроль'!$AF19,0) -> 0.181125 | BL18: =IF(BL$1=$D20,'Данные, контроль'!$AF19,0) -> 0 | BM18: =IF(BM$1=$D20,'Данные, контроль'!$AF19,0) -> 0 | BN18: =IF(BN$1=$D20,'Данные, контроль'!$AF19,0) -> 0 | BO18: =IF(BO$1=$D20,'Данные, контроль'!$AF19,0) -> 0 | BP18: =IF(BP$1=$D20,'Данные, контроль'!$AF19,0) -> 0 | BQ18: =IF(BQ$1=$D20,'Данные, контроль'!$AF19,0) -> 0 | ... EH18: =IF(EH$1=$D20,'Данные, контроль'!$AF19,0) -> 0
A19: 4701 | B19: 2016 | C19: компьютерных технологий и электронного обучения | D19: Карпова Наталья Александровна | E19: кандидат технических наук | F19: доцент | G19: 0.5 | H19: 15313 | I19: Информационные технологии | J19: =[1]Данные!J18 -> 17 | K19: =[1]Данные!K18 -> 0 | L19: =[1]Данные!L18 -> 102 | M19: =(J19 + K19 + L19)*0.1 -> 11.9 | N19: =2+(0.33*W19) -> 2 | O19: =0.25*W19 -> 0 | P19: =0.25*W19 -> 0 | Q19: =[1]Данные!Q18 -> 0 | R19: =[1]Данные!R18 -> 0 | S19: =[1]Данные!S18 -> 0 | T19: =[1]Данные!T18 -> 12 | U19: =[1]Данные!U18 -> 0 | V19: =[1]Данные!V18 -> 0 | W19: =[1]Данные!W18 -> 0 | X19: =[1]Данные!X18 -> 0 | ... Z19: =[1]Данные!Z18 -> 0 | AA19: осн | BJ19: =IF(BJ$1=$D21,'Данные, контроль'!$AF20,0) -> 0 | BK19: =IF(BK$1=$D21,'Данные, контроль'!$AF20,0) -> 0 | BL19: =IF(BL$1=$D21,'Данные, контроль'!$AF20,0) -> 0.15733333 | BM19: =IF(BM$1=$D21,'Данные, контроль'!$AF20,0) -> 0 | BN19: =IF(BN$1=$D21,'Данные, контроль'!$AF20,0) -> 0 | BO19: =IF(BO$1=$D21,'Данные, контроль'!$AF20,0) -> 0 | BP19: =IF(BP$1=$D21,'Данные, контроль'!$AF20,0) -> 0 | BQ19: =IF(BQ$1=$D21,'Данные, контроль'!$AF20,0) -> 0 | ... EH19: =IF(EH$1=$D21,'Данные, контроль'!$AF20,0) -> 0
A20: 4755 | B20: 2016 | C20: компьютерных технологий и электронного обучения | D20: Абрамян Геннадий Владимирович | E20: доктор педагогических наук | F20: профессор | G20: 1 | H20: 15058 | I20: Информационное обеспечение технологического образования. Применение Интернет-технологий в технологическом образовании | J20: =[1]Данные!J19 -> 18 | K20: =[1]Данные!K19 -> 0 | L20: =[1]Данные!L19 -> 72 | M20: =(J20 + K20 + L20)*0.1 -> 9 | N20: =2+(0.33*W20) -> 2 | O20: =0.25*W20 -> 0 | P20: =0.25*W20 -> 0 | Q20: =[1]Данные!Q19 -> 0 | R20: =[1]Данные!R19 -> 0 | S20: =[1]Данные!S19 -> 0 | T20: =[1]Данные!T19 -> 17 | U20: =[1]Данные!U19 -> 0 | V20: =[1]Данные!V19 -> 0 | W20: =[1]Данные!W19 -> 0 | X20: =[1]Данные!X19 -> 0 | ... Z20: =[1]Данные!Z19 -> 0 | AA20: осн | BJ20: =IF(BJ$1=$D22,'Данные, контроль'!$AF21,0) -> 0 | BK20: =IF(BK$1=$D22,'Данные, контроль'!$AF21,0) -> 0 | BL20: =IF(BL$1=$D22,'Данные, контроль'!$AF21,0) -> 0 | BM20: =IF(BM$1=$D22,'Данные, контроль'!$AF21,0) -> 0 | BN20: =IF(BN$1=$D22,'Данные, контроль'!$AF21,0) -> 0 | BO20: =IF(BO$1=$D22,'Данные, контроль'!$AF21,0) -> 0 | BP20: =IF(BP$1=$D22,'Данные, контроль'!$AF21,0) -> 0 | BQ20: =IF(BQ$1=$D22,'Данные, контроль'!$AF21,0) -> 0 | ... EH20: =IF(EH$1=$D22,'Данные, контроль'!$AF21,0) -> 0
A21: 4755 | B21: 2016 | C21: компьютерных технологий и электронного обучения | D21: Авксентьева Елена Юрьевна | E21: кандидат педагогических наук | F21: доцент | G21: 1 | H21: 15058 | I21: Информационные технологии | J21: =[1]Данные!J20 -> 0 | K21: =[1]Данные!K20 -> 96 | L21: =[1]Данные!L20 -> 0 | M21: =(J21 + K21 + L21)*0.1 -> 9.6 | N21: =2+(0.33*W21) -> 2 | O21: =0.25*W21 -> 0 | P21: =0.25*W21 -> 0 | Q21: =[1]Данные!Q20 -> 0 | R21: =[1]Данные!R20 -> 0 | S21: =[1]Данные!S20 -> 0 | T21: =[1]Данные!T20 -> 12 | U21: =[1]Данные!U20 -> 0 | V21: =[1]Данные!V20 -> 0 | W21: =[1]Данные!W20 -> 0 | X21: =[1]Данные!X20 -> 0 | ... Z21: =[1]Данные!Z20 -> 0 | AA21: осн | BJ21: =IF(BJ$1=$D23,'Данные, контроль'!$AF22,0) -> 0 | BK21: =IF(BK$1=$D23,'Данные, контроль'!$AF22,0) -> 0 | BL21: =IF(BL$1=$D23,'Данные, контроль'!$AF22,0) -> 0 | BM21: =IF(BM$1=$D23,'Данные, контроль'!$AF22,0) -> 0 | BN21: =IF(BN$1=$D23,'Данные, контроль'!$AF22,0) -> 0 | BO21: =IF(BO$1=$D23,'Данные, контроль'!$AF22,0) -> 0 | BP21: =IF(BP$1=$D23,'Данные, контроль'!$AF22,0) -> 0 | BQ21: =IF(BQ$1=$D23,'Данные, контроль'!$AF22,0) -> 0 | ... EH21: =IF(EH$1=$D23,'Данные, контроль'!$AF22,0) -> 0
A22: 4755 | B22: 2016 | C22: компьютерных технологий и электронного обучения | D22: Карпова Наталья Александровна | E22: кандидат технических наук | F22: доцент | G22: 1 | H22: 15058 | I22: Информационное обеспечение технологического образования. Применение Интернет-технологий в технологическом образовании | J22: =[1]Данные!J21 -> 0 | K22: =[1]Данные!K21 -> 0 | L22: =[1]Данные!L21 -> 0 | M22: =(J22 + K22 + L22)*0.1 -> 0 | N22: =2+(0.33*W22) -> 2 | O22: =0.25*W22 -> 0 | P22: =0.25*W22 -> 0 | Q22: =[1]Данные!Q21 -> 0 | R22: =[1]Данные!R21 -> 0 | S22: =[1]Данные!S21 -> 0 | T22: =[1]Данные!T21 -> 2 | U22: =[1]Данные!U21 -> 0 | V22: =[1]Данные!V21 -> 0 | W22: =[1]Данные!W21 -> 0 | X22: =[1]Данные!X21 -> 0 | ... Z22: =[1]Данные!Z21 -> 0 | AA22: осн | BJ22: =IF(BJ$1=$D24,'Данные, контроль'!$AF23,0) -> 0 | BK22: =IF(BK$1=$D24,'Данные, контроль'!$AF23,0) -> 0 | BL22: =IF(BL$1=$D24,'Данные, контроль'!$AF23,0) -> 0 | BM22: =IF(BM$1=$D24,'Данные, контроль'!$AF23,0) -> 0 | BN22: =IF(BN$1=$D24,'Данные, контроль'!$AF23,0) -> 0 | BO22: =IF(BO$1=$D24,'Данные, контроль'!$AF23,0) -> 0 | BP22: =IF(BP$1=$D24,'Данные, контроль'!$AF23,0) -> 0 | BQ22: =IF(BQ$1=$D24,'Данные, контроль'!$AF23,0) -> 0 | ... EH22: =IF(EH$1=$D24,'Данные, контроль'!$AF23,0) -> 0
A23: 4755 | B23: 2016 | C23: компьютерных технологий и электронного обучения | D23: Полякова Наталия Александровна | E23: кандидат педагогических наук | F23: доцент | G23: 1 | H23: 15058 | I23: Информационные технологии | J23: =[1]Данные!J22 -> 9 | K23: =[1]Данные!K22 -> 0 | L23: =[1]Данные!L22 -> 0 | M23: =(J23 + K23 + L23)*0.1 -> 0.9 | N23: =2+(0.33*W23) -> 2 | O23: =0.25*W23 -> 0 | P23: =0.25*W23 -> 0 | Q23: =[1]Данные!Q22 -> 0 | R23: =[1]Данные!R22 -> 0 | S23: =[1]Данные!S22 -> 0 | T23: =[1]Данные!T22 -> 0 | U23: =[1]Данные!U22 -> 0 | V23: =[1]Данные!V22 -> 0 | W23: =[1]Данные!W22 -> 0 | X23: =[1]Данные!X22 -> 0 | ... Z23: =[1]Данные!Z22 -> 0 | AA23: осн | BJ23: =IF(BJ$1=$D25,'Данные, контроль'!$AF24,0) -> 0 | BK23: =IF(BK$1=$D25,'Данные, контроль'!$AF24,0) -> 0 | BL23: =IF(BL$1=$D25,'Данные, контроль'!$AF24,0) -> 0 | BM23: =IF(BM$1=$D25,'Данные, контроль'!$AF24,0) -> 0 | BN23: =IF(BN$1=$D25,'Данные, контроль'!$AF24,0) -> 0 | BO23: =IF(BO$1=$D25,'Данные, контроль'!$AF24,0) -> 0 | BP23: =IF(BP$1=$D25,'Данные, контроль'!$AF24,0) -> 0 | BQ23: =IF(BQ$1=$D25,'Данные, контроль'!$AF24,0) -> 0 | ... EH23: =IF(EH$1=$D25,'Данные, контроль'!$AF24,0) -> 0
A24: 4755 | B24: 2017 | C24: компьютерных технологий и электронного обучения | D24: Готская Ирина Борисовна | E24: доктор педагогических наук | F24: профессор | G24: 1 | H24: 16007 | I24: Информационное обеспечение технологического образования. Применение электронных образовательных ресурсов в технологическом образовании | J24: =[1]Данные!J23 -> 32 | K24: =[1]Данные!K23 -> 0 | L24: =[1]Данные!L23 -> 160 | M24: =(J24 + K24 + L24)*0.1 -> 19.2 | N24: =2+(0.33*W24) -> 2 | O24: =0.25*W24 -> 0 | P24: =0.25*W24 -> 0 | Q24: =[1]Данные!Q23 -> 0 | R24: =[1]Данные!R23 -> 0 | S24: =[1]Данные!S23 -> 0 | T24: =[1]Данные!T23 -> 22 | U24: =[1]Данные!U23 -> 0 | V24: =[1]Данные!V23 -> 0 | W24: =[1]Данные!W23 -> 0 | X24: =[1]Данные!X23 -> 0 | ... Z24: =[1]Данные!Z23 -> 0 | AA24: осн | BJ24: =IF(BJ$1=$D26,'Данные, контроль'!$AF25,0) -> 0 | BK24: =IF(BK$1=$D26,'Данные, контроль'!$AF25,0) -> 0.1608 | BL24: =IF(BL$1=$D26,'Данные, контроль'!$AF25,0) -> 0 | BM24: =IF(BM$1=$D26,'Данные, контроль'!$AF25,0) -> 0 | BN24: =IF(BN$1=$D26,'Данные, контроль'!$AF25,0) -> 0 | BO24: =IF(BO$1=$D26,'Данные, контроль'!$AF25,0) -> 0 | BP24: =IF(BP$1=$D26,'Данные, контроль'!$AF25,0) -> 0 | BQ24: =IF(BQ$1=$D26,'Данные, контроль'!$AF25,0) -> 0 | ... EH24: =IF(EH$1=$D26,'Данные, контроль'!$AF25,0) -> 0
A25: 4755 | B25: 2018 | C25: компьютерных технологий и электронного обучения | D25: Готская Ирина Борисовна | E25: доктор педагогических наук | F25: профессор | G25: 0.75 | H25: 17235 | I25: Информационное обеспечение технологического образования. Информационное обеспечение инновационной технологической деятельности | J25: =[1]Данные!J24 -> 16 | K25: =[1]Данные!K24 -> 0 | L25: =[1]Данные!L24 -> 80 | M25: =(J25 + K25 + L25)*0.1 -> 9.6 | N25: =2+(0.33*W25) -> 2 | O25: =0.25*W25 -> 0 | P25: =0.25*W25 -> 0 | Q25: =[1]Данные!Q24 -> 0 | R25: =[1]Данные!R24 -> 0 | S25: =[1]Данные!S24 -> 0 | T25: =[1]Данные!T24 -> 13 | U25: =[1]Данные!U24 -> 0 | V25: =[1]Данные!V24 -> 0 | W25: =[1]Данные!W24 -> 0 | X25: =[1]Данные!X24 -> 0 | ... Z25: =[1]Данные!Z24 -> 0 | AA25: осн | BJ25: =IF(BJ$1=$D27,'Данные, контроль'!$AF26,0) -> 0 | BK25: =IF(BK$1=$D27,'Данные, контроль'!$AF26,0) -> 0 | BL25: =IF(BL$1=$D27,'Данные, контроль'!$AF26,0) -> 0 | BM25: =IF(BM$1=$D27,'Данные, контроль'!$AF26,0) -> 0 | BN25: =IF(BN$1=$D27,'Данные, контроль'!$AF26,0) -> 0 | BO25: =IF(BO$1=$D27,'Данные, контроль'!$AF26,0) -> 0 | BP25: =IF(BP$1=$D27,'Данные, контроль'!$AF26,0) -> 0 | BQ25: =IF(BQ$1=$D27,'Данные, контроль'!$AF26,0) -> 0 | ... EH25: =IF(EH$1=$D27,'Данные, контроль'!$AF26,0) -> 0
A26: 4848 | B26: 2015 | C26: компьютерных технологий и электронного обучения | D26: Абрамян Геннадий Владимирович | E26: доктор педагогических наук | F26: профессор | G26: 1 | H26: 14014 | I26: ЭВМ и периферийные устройства | J26: =[1]Данные!J25 -> 42 | K26: =[1]Данные!K25 -> 0 | L26: =[1]Данные!L25 -> 42 | M26: =(J26 + K26 + L26)*0.1 -> 8.4 | N26: =2+(0.33*W26) -> 2 | O26: =0.25*W26 -> 0 | P26: =0.25*W26 -> 0 | Q26: =[1]Данные!Q25 -> 0 | R26: =[1]Данные!R25 -> 0 | S26: =[1]Данные!S25 -> 0 | T26: =[1]Данные!T25 -> 0 | U26: =[1]Данные!U25 -> 0 | V26: =[1]Данные!V25 -> 0 | W26: =[1]Данные!W25 -> 0 | X26: =[1]Данные!X25 -> 0 | ... Z26: =[1]Данные!Z25 -> 0 | AA26: осн | BJ26: =IF(BJ$1=$D28,'Данные, контроль'!$AF27,0) -> 0 | BK26: =IF(BK$1=$D28,'Данные, контроль'!$AF27,0) -> 0 | BL26: =IF(BL$1=$D28,'Данные, контроль'!$AF27,0) -> 0 | BM26: =IF(BM$1=$D28,'Данные, контроль'!$AF27,0) -> 0 | BN26: =IF(BN$1=$D28,'Данные, контроль'!$AF27,0) -> 0 | BO26: =IF(BO$1=$D28,'Данные, контроль'!$AF27,0) -> 0 | BP26: =IF(BP$1=$D28,'Данные, контроль'!$AF27,0) -> 0 | BQ26: =IF(BQ$1=$D28,'Данные, контроль'!$AF27,0) -> 0 | ... EH26: =IF(EH$1=$D28,'Данные, контроль'!$AF27,0) -> 0
A27: 4848 | B27: 2015 | C27: компьютерных технологий и электронного обучения | D27: Власова Елена Зотиковна | E27: доктор педагогических наук | F27: заведующий кафедрой | G27: 1 | H27: 14014 | I27: Информатика | J27: =[1]Данные!J26 -> 17 | K27: =[1]Данные!K26 -> 17 | L27: =[1]Данные!L26 -> 0 | M27: =(J27 + K27 + L27)*0.1 -> 3.4 | N27: =2+(0.33*W27) -> 2 | O27: =0.25*W27 -> 0 | P27: =0.25*W27 -> 0 | Q27: =[1]Данные!Q26 -> 0 | R27: =[1]Данные!R26 -> 0 | S27: =[1]Данные!S26 -> 0 | T27: =[1]Данные!T26 -> 0 | U27: =[1]Данные!U26 -> 0 | V27: =[1]Данные!V26 -> 0 | W27: =[1]Данные!W26 -> 0 | X27: =[1]Данные!X26 -> 0 | ... Z27: =[1]Данные!Z26 -> 0 | AA27: осн | BJ27: =IF(BJ$1=$D29,'Данные, контроль'!$AF28,0) -> 0 | BK27: =IF(BK$1=$D29,'Данные, контроль'!$AF28,0) -> 0 | BL27: =IF(BL$1=$D29,'Данные, контроль'!$AF28,0) -> 0 | BM27: =IF(BM$1=$D29,'Данные, контроль'!$AF28,0) -> 0 | BN27: =IF(BN$1=$D29,'Данные, контроль'!$AF28,0) -> 0 | BO27: =IF(BO$1=$D29,'Данные, контроль'!$AF28,0) -> 0 | BP27: =IF(BP$1=$D29,'Данные, контроль'!$AF28,0) -> 0 | BQ27: =IF(BQ$1=$D29,'Данные, контроль'!$AF28,0) -> 0 | ... EH27: =IF(EH$1=$D29,'Данные, контроль'!$AF28,0) -> 0
A28: 4848 | B28: 2015 | C28: компьютерных технологий и электронного обучения | D28: Власова Елена Зотиковна | E28: доктор педагогических наук | F28: заведующий кафедрой | G28: 1 | H28: 14014 | I28: Программирование | J28: =[1]Данные!J27 -> 13 | K28: =[1]Данные!K27 -> 0 | L28: =[1]Данные!L27 -> 23 | M28: =(J28 + K28 + L28)*0.1 -> 3.6 | N28: =2+(0.33*W28) -> 2 | O28: =0.25*W28 -> 0 | P28: =0.25*W28 -> 0 | Q28: =[1]Данные!Q27 -> 0 | R28: =[1]Данные!R27 -> 0 | S28: =[1]Данные!S27 -> 0 | T28: =[1]Данные!T27 -> 0 | U28: =[1]Данные!U27 -> 0 | V28: =[1]Данные!V27 -> 0 | W28: =[1]Данные!W27 -> 0 | X28: =[1]Данные!X27 -> 0 | ... Z28: =[1]Данные!Z27 -> 0 | AA28: осн | BJ28: =IF(BJ$1=$D30,'Данные, контроль'!$AF29,0) -> 0 | BK28: =IF(BK$1=$D30,'Данные, контроль'!$AF29,0) -> 0 | BL28: =IF(BL$1=$D30,'Данные, контроль'!$AF29,0) -> 0 | BM28: =IF(BM$1=$D30,'Данные, контроль'!$AF29,0) -> 0 | BN28: =IF(BN$1=$D30,'Данные, контроль'!$AF29,0) -> 0 | BO28: =IF(BO$1=$D30,'Данные, контроль'!$AF29,0) -> 0 | BP28: =IF(BP$1=$D30,'Данные, контроль'!$AF29,0) -> 0 | BQ28: =IF(BQ$1=$D30,'Данные, контроль'!$AF29,0) -> 0 | ... EH28: =IF(EH$1=$D30,'Данные, контроль'!$AF29,0) -> 0
... A42: 4848 | B42: 2016 | C42: компьютерных технологий и электронного обучения | D42: Абрамян Геннадий Владимирович | E42: доктор педагогических наук | F42: профессор | G42: 1 | H42: 15377 | I42: Операционные системы | J42: =[1]Данные!J41 -> 4 | K42: =[1]Данные!K41 -> 14 | L42: =[1]Данные!L41 -> 14 | M42: =(J42 + K42 + L42)*0.1 -> 3.2 | N42: =2+(0.33*W42) -> 2 | O42: =0.25*W42 -> 0 | P42: =0.25*W42 -> 0 | Q42: =[1]Данные!Q41 -> 0 | R42: =[1]Данные!R41 -> 0 | S42: =[1]Данные!S41 -> 0 | T42: =[1]Данные!T41 -> 0 | U42: =[1]Данные!U41 -> 0 | V42: =[1]Данные!V41 -> 0 | W42: =[1]Данные!W41 -> 0 | X42: =[1]Данные!X41 -> 0 | ... Z42: =[1]Данные!Z41 -> 0 | AA42: осн | BJ42: =IF(BJ$1=$D44,'Данные, контроль'!$AF43,0) -> 0 | BK42: =IF(BK$1=$D44,'Данные, контроль'!$AF43,0) -> 0 | BL42: =IF(BL$1=$D44,'Данные, контроль'!$AF43,0) -> 0.052533333 | BM42: =IF(BM$1=$D44,'Данные, контроль'!$AF43,0) -> 0 | BN42: =IF(BN$1=$D44,'Данные, контроль'!$AF43,0) -> 0 | BO42: =IF(BO$1=$D44,'Данные, контроль'!$AF43,0) -> 0 | BP42: =IF(BP$1=$D44,'Данные, контроль'!$AF43,0) -> 0 | BQ42: =IF(BQ$1=$D44,'Данные, контроль'!$AF43,0) -> 0 | ... EH42: =IF(EH$1=$D44,'Данные, контроль'!$AF43,0) -> 0
A43: 4848 | B43: 2016 | C43: компьютерных технологий и электронного обучения | D43: Абрамян Геннадий Владимирович | E43: доктор педагогических наук | F43: профессор | G43: 1 | H43: 15377 | I43: Программирование | J43: =[1]Данные!J42 -> 34 | K43: =[1]Данные!K42 -> 0 | L43: =[1]Данные!L42 -> 0 | M43: =(J43 + K43 + L43)*0.1 -> 3.4 | N43: =2+(0.33*W43) -> 2 | O43: =0.25*W43 -> 0 | P43: =0.25*W43 -> 0 | Q43: =[1]Данные!Q42 -> 0 | R43: =[1]Данные!R42 -> 0 | S43: =[1]Данные!S42 -> 0 | T43: =[1]Данные!T42 -> 0 | U43: =[1]Данные!U42 -> 0 | V43: =[1]Данные!V42 -> 0 | W43: =[1]Данные!W42 -> 0 | X43: =[1]Данные!X42 -> 0 | ... Z43: =[1]Данные!Z42 -> 0 | BJ43: =IF(BJ$1=$D45,'Данные, контроль'!$AF44,0) -> 0 | BK43: =IF(BK$1=$D45,'Данные, контроль'!$AF44,0) -> 0 | BL43: =IF(BL$1=$D45,'Данные, контроль'!$AF44,0) -> 0 | BM43: =IF(BM$1=$D45,'Данные, контроль'!$AF44,0) -> 0 | BN43: =IF(BN$1=$D45,'Данные, контроль'!$AF44,0) -> 0 | BO43: =IF(BO$1=$D45,'Данные, контроль'!$AF44,0) -> 0 | BP43: =IF(BP$1=$D45,'Данные, контроль'!$AF44,0) -> 0 | BQ43: =IF(BQ$1=$D45,'Данные, контроль'!$AF44,0) -> 0 | ... EH43: =IF(EH$1=$D45,'Данные, контроль'!$AF44,0) -> 0
A44: 4848 | B44: 2016 | C44: компьютерных технологий и электронного обучения | D44: Авксентьева Елена Юрьевна | E44: кандидат педагогических наук | F44: доцент | G44: 1 | H44: 15377 | I44: Модуль "Технологии и методы вычислений". Информационные технологии в решении задач оптимизации | J44: =[1]Данные!J43 -> 18 | K44: =[1]Данные!K43 -> 0 | L44: =[1]Данные!L43 -> 18 | M44: =(J44 + K44 + L44)*0.1 -> 3.6 | N44: =2+(0.33*W44) -> 2 | O44: =0.25*W44 -> 0 | P44: =0.25*W44 -> 0 | Q44: =[1]Данные!Q43 -> 0 | R44: =[1]Данные!R43 -> 0 | S44: =[1]Данные!S43 -> 0 | T44: =[1]Данные!T43 -> 0 | U44: =[1]Данные!U43 -> 0 | V44: =[1]Данные!V43 -> 0 | W44: =[1]Данные!W43 -> 0 | X44: =[1]Данные!X43 -> 0 | ... Z44: =[1]Данные!Z43 -> 0 | AA44: осн | BJ44: =IF(BJ$1=$D46,'Данные, контроль'!$AF45,0) -> 0 | BK44: =IF(BK$1=$D46,'Данные, контроль'!$AF45,0) -> 0 | BL44: =IF(BL$1=$D46,'Данные, контроль'!$AF45,0) -> 0 | BM44: =IF(BM$1=$D46,'Данные, контроль'!$AF45,0) -> 0 | BN44: =IF(BN$1=$D46,'Данные, контроль'!$AF45,0) -> 0 | BO44: =IF(BO$1=$D46,'Данные, контроль'!$AF45,0) -> 0 | BP44: =IF(BP$1=$D46,'Данные, контроль'!$AF45,0) -> 0 | BQ44: =IF(BQ$1=$D46,'Данные, контроль'!$AF45,0) -> 0 | ... EH44: =IF(EH$1=$D46,'Данные, контроль'!$AF45,0) -> 0
A45: 4848 | B45: 2016 | C45: компьютерных технологий и электронного обучения | D45: Власова Елена Зотиковна | E45: доктор педагогических наук | F45: заведующий кафедрой | G45: 1 | H45: 15377 | I45: Модуль "Технологии и методы вычислений" | J45: =[1]Данные!J44 -> 0 | K45: =[1]Данные!K44 -> 0 | L45: =[1]Данные!L44 -> 0 | M45: =(J45 + K45 + L45)*0.1 -> 0 | N45: =2+(0.33*W45) -> 2 | O45: =0.25*W45 -> 0 | P45: =0.25*W45 -> 0 | Q45: =[1]Данные!Q44 -> 0 | R45: =[1]Данные!R44 -> 0 | S45: =[1]Данные!S44 -> 0 | T45: =[1]Данные!T44 -> 0 | U45: =[1]Данные!U44 -> 0 | V45: =[1]Данные!V44 -> 0 | W45: =[1]Данные!W44 -> 0 | X45: =[1]Данные!X44 -> 0 | ... Z45: =[1]Данные!Z44 -> 0 | AA45: осн | BJ45: =IF(BJ$1=$D47,'Данные, контроль'!$AF46,0) -> 0 | BK45: =IF(BK$1=$D47,'Данные, контроль'!$AF46,0) -> 0 | BL45: =IF(BL$1=$D47,'Данные, контроль'!$AF46,0) -> 0 | BM45: =IF(BM$1=$D47,'Данные, контроль'!$AF46,0) -> 0 | BN45: =IF(BN$1=$D47,'Данные, контроль'!$AF46,0) -> 0 | BO45: =IF(BO$1=$D47,'Данные, контроль'!$AF46,0) -> 0 | BP45: =IF(BP$1=$D47,'Данные, контроль'!$AF46,0) -> 0 | BQ45: =IF(BQ$1=$D47,'Данные, контроль'!$AF46,0) -> 0 | ... EH45: =IF(EH$1=$D47,'Данные, контроль'!$AF46,0) -> 0
A46: 4848 | B46: 2016 | C46: компьютерных технологий и электронного обучения | D46: Власова Елена Зотиковна | E46: доктор педагогических наук | F46: заведующий кафедрой | G46: 1 | H46: 15377 | I46: Модуль "Технологии и методы вычислений". Анализ данных | J46: =[1]Данные!J45 -> 17 | K46: =[1]Данные!K45 -> 0 | L46: =[1]Данные!L45 -> 0 | M46: =(J46 + K46 + L46)*0.1 -> 1.7 | N46: =2+(0.33*W46) -> 2 | O46: =0.25*W46 -> 0 | P46: =0.25*W46 -> 0 | Q46: =[1]Данные!Q45 -> 0 | R46: =[1]Данные!R45 -> 0 | S46: =[1]Данные!S45 -> 0 | T46: =[1]Данные!T45 -> 0 | U46: =[1]Данные!U45 -> 0 | V46: =[1]Данные!V45 -> 0 | W46: =[1]Данные!W45 -> 0 | X46: =[1]Данные!X45 -> 0 | ... Z46: =[1]Данные!Z45 -> 0 | AA46: осн | BJ46: =IF(BJ$1=$D48,'Данные, контроль'!$AF47,0) -> 0 | BK46: =IF(BK$1=$D48,'Данные, контроль'!$AF47,0) -> 0 | BL46: =IF(BL$1=$D48,'Данные, контроль'!$AF47,0) -> 0 | BM46: =IF(BM$1=$D48,'Данные, контроль'!$AF47,0) -> 0 | BN46: =IF(BN$1=$D48,'Данные, контроль'!$AF47,0) -> 0 | BO46: =IF(BO$1=$D48,'Данные, контроль'!$AF47,0) -> 0 | BP46: =IF(BP$1=$D48,'Данные, контроль'!$AF47,0) -> 0 | BQ46: =IF(BQ$1=$D48,'Данные, контроль'!$AF47,0) -> 0 | ... EH46: =IF(EH$1=$D48,'Данные, контроль'!$AF47,0) -> 0
A47: 4848 | B47: 2016 | C47: компьютерных технологий и электронного обучения | D47: Власова Елена Зотиковна | E47: доктор педагогических наук | F47: заведующий кафедрой | G47: 1 | H47: 15377 | I47: Модуль "Технологии и методы вычислений". Вычислительная математика | J47: =[1]Данные!J46 -> 17 | K47: =[1]Данные!K46 -> 0 | L47: =[1]Данные!L46 -> 0 | M47: =(J47 + K47 + L47)*0.1 -> 1.7 | N47: =2+(0.33*W47) -> 2 | O47: =0.25*W47 -> 0 | P47: =0.25*W47 -> 0 | Q47: =[1]Данные!Q46 -> 0 | R47: =[1]Данные!R46 -> 0 | S47: =[1]Данные!S46 -> 0 | T47: =[1]Данные!T46 -> 0 | U47: =[1]Данные!U46 -> 0 | V47: =[1]Данные!V46 -> 0 | W47: =[1]Данные!W46 -> 0 | X47: =[1]Данные!X46 -> 0 | ... Z47: =[1]Данные!Z46 -> 0 | AA47: осн | BJ47: =IF(BJ$1=$D49,'Данные, контроль'!$AF48,0) -> 0 | BK47: =IF(BK$1=$D49,'Данные, контроль'!$AF48,0) -> 0 | BL47: =IF(BL$1=$D49,'Данные, контроль'!$AF48,0) -> 0 | BM47: =IF(BM$1=$D49,'Данные, контроль'!$AF48,0) -> 0 | BN47: =IF(BN$1=$D49,'Данные, контроль'!$AF48,0) -> 0 | BO47: =IF(BO$1=$D49,'Данные, контроль'!$AF48,0) -> 0 | BP47: =IF(BP$1=$D49,'Данные, контроль'!$AF48,0) -> 0 | BQ47: =IF(BQ$1=$D49,'Данные, контроль'!$AF48,0) -> 0 | ... EH47: =IF(EH$1=$D49,'Данные, контроль'!$AF48,0) -> 0
A48: 4848 | B48: 2016 | C48: компьютерных технологий и электронного обучения | D48: Власова Елена Зотиковна | E48: доктор педагогических наук | F48: заведующий кафедрой | G48: 1 | H48: 15377 | I48: Модуль "Технологии и методы вычислений". Технологии компьютерного моделирования | J48: =[1]Данные!J47 -> 18 | K48: =[1]Данные!K47 -> 0 | L48: =[1]Данные!L47 -> 27 | M48: =(J48 + K48 + L48)*0.1 -> 4.5 | N48: =2+(0.33*W48) -> 2 | O48: =0.25*W48 -> 0 | P48: =0.25*W48 -> 0 | Q48: =[1]Данные!Q47 -> 0 | R48: =[1]Данные!R47 -> 0 | S48: =[1]Данные!S47 -> 0 | T48: =[1]Данные!T47 -> 0 | U48: =[1]Данные!U47 -> 0 | V48: =[1]Данные!V47 -> 0 | W48: =[1]Данные!W47 -> 0 | X48: =[1]Данные!X47 -> 0 | ... Z48: =[1]Данные!Z47 -> 0 | AA48: осн | BJ48: =IF(BJ$1=$D50,'Данные, контроль'!$AF49,0) -> 0 | BK48: =IF(BK$1=$D50,'Данные, контроль'!$AF49,0) -> 0 | BL48: =IF(BL$1=$D50,'Данные, контроль'!$AF49,0) -> 0 | BM48: =IF(BM$1=$D50,'Данные, контроль'!$AF49,0) -> 0 | BN48: =IF(BN$1=$D50,'Данные, контроль'!$AF49,0) -> 0 | BO48: =IF(BO$1=$D50,'Данные, контроль'!$AF49,0) -> 0 | BP48: =IF(BP$1=$D50,'Данные, контроль'!$AF49,0) -> 0 | BQ48: =IF(BQ$1=$D50,'Данные, контроль'!$AF49,0) -> 0 | ... EH48: =IF(EH$1=$D50,'Данные, контроль'!$AF49,0) -> 0
A49: 4848 | B49: 2016 | C49: компьютерных технологий и электронного обучения | D49: Гончарова Светлана Викторовна | E49: кандидат педагогических наук | F49: доцент | G49: 1 | H49: 15377 | I49: Модуль "Технологии и методы вычислений" | J49: =[1]Данные!J48 -> 0 | K49: =[1]Данные!K48 -> 0 | L49: =[1]Данные!L48 -> 0 | M49: =(J49 + K49 + L49)*0.1 -> 0 | N49: =2+(0.33*W49) -> 2 | O49: =0.25*W49 -> 0 | P49: =0.25*W49 -> 0 | Q49: =[1]Данные!Q48 -> 0 | R49: =[1]Данные!R48 -> 0 | S49: =[1]Данные!S48 -> 0 | T49: =[1]Данные!T48 -> 0 | U49: =[1]Данные!U48 -> 0 | V49: =[1]Данные!V48 -> 0 | W49: =[1]Данные!W48 -> 0 | X49: =[1]Данные!X48 -> 0 | ... Z49: =[1]Данные!Z48 -> 0 | AA49: осн | BJ49: =IF(BJ$1=$D51,'Данные, контроль'!$AF50,0) -> 0 | BK49: =IF(BK$1=$D51,'Данные, контроль'!$AF50,0) -> 0 | BL49: =IF(BL$1=$D51,'Данные, контроль'!$AF50,0) -> 0 | BM49: =IF(BM$1=$D51,'Данные, контроль'!$AF50,0) -> 0 | BN49: =IF(BN$1=$D51,'Данные, контроль'!$AF50,0) -> 0 | BO49: =IF(BO$1=$D51,'Данные, контроль'!$AF50,0) -> 0 | BP49: =IF(BP$1=$D51,'Данные, контроль'!$AF50,0) -> 0 | BQ49: =IF(BQ$1=$D51,'Данные, контроль'!$AF50,0) -> 0 | ... EH49: =IF(EH$1=$D51,'Данные, контроль'!$AF50,0) -> 0
A50: 4848 | B50: 2016 | C50: компьютерных технологий и электронного обучения | D50: Гончарова Светлана Викторовна | E50: кандидат педагогических наук | F50: доцент | G50: 1 | H50: 15377 | I50: Модуль "Технологии и методы вычислений". Анализ данных | J50: =[1]Данные!J49 -> 0 | K50: =[1]Данные!K49 -> 0 | L50: =[1]Данные!L49 -> 34 | M50: =(J50 + K50 + L50)*0.1 -> 3.4 | N50: =2+(0.33*W50) -> 2 | O50: =0.25*W50 -> 0 | P50: =0.25*W50 -> 0 | Q50: =[1]Данные!Q49 -> 0 | R50: =[1]Данные!R49 -> 0 | S50: =[1]Данные!S49 -> 0 | T50: =[1]Данные!T49 -> 0 | U50: =[1]Данные!U49 -> 0 | V50: =[1]Данные!V49 -> 0 | W50: =[1]Данные!W49 -> 0 | X50: =[1]Данные!X49 -> 0 | ... Z50: =[1]Данные!Z49 -> 0 | AA50: осн | BJ50: =IF(BJ$1=$D52,'Данные, контроль'!$AF51,0) -> 0 | BK50: =IF(BK$1=$D52,'Данные, контроль'!$AF51,0) -> 0 | BL50: =IF(BL$1=$D52,'Данные, контроль'!$AF51,0) -> 0 | BM50: =IF(BM$1=$D52,'Данные, контроль'!$AF51,0) -> 0 | BN50: =IF(BN$1=$D52,'Данные, контроль'!$AF51,0) -> 0 | BO50: =IF(BO$1=$D52,'Данные, контроль'!$AF51,0) -> 0 | BP50: =IF(BP$1=$D52,'Данные, контроль'!$AF51,0) -> 0 | BQ50: =IF(BQ$1=$D52,'Данные, контроль'!$AF51,0) -> 0 | ... EH50: =IF(EH$1=$D52,'Данные, контроль'!$AF51,0) -> 0
A51: 4848 | B51: 2016 | C51: компьютерных технологий и электронного обучения | D51: Гончарова Светлана Викторовна | E51: кандидат педагогических наук | F51: доцент | G51: 1 | H51: 15377 | I51: Модуль "Технологии и методы вычислений". Технологии компьютерного моделирования | J51: =[1]Данные!J50 -> 0 | K51: =[1]Данные!K50 -> 0 | L51: =[1]Данные!L50 -> 27 | M51: =(J51 + K51 + L51)*0.1 -> 2.7 | N51: =2+(0.33*W51) -> 2 | O51: =0.25*W51 -> 0 | P51: =0.25*W51 -> 0 | Q51: =[1]Данные!Q50 -> 0 | R51: =[1]Данные!R50 -> 0 | S51: =[1]Данные!S50 -> 0 | T51: =[1]Данные!T50 -> 0 | U51: =[1]Данные!U50 -> 0 | V51: =[1]Данные!V50 -> 0 | W51: =[1]Данные!W50 -> 0 | X51: =[1]Данные!X50 -> 0 | ... Z51: =[1]Данные!Z50 -> 0 | AA51: осн | BJ51: =IF(BJ$1=$D53,'Данные, контроль'!$AF52,0) -> 0 | BK51: =IF(BK$1=$D53,'Данные, контроль'!$AF52,0) -> 0 | BL51: =IF(BL$1=$D53,'Данные, контроль'!$AF52,0) -> 0 | BM51: =IF(BM$1=$D53,'Данные, контроль'!$AF52,0) -> 0 | BN51: =IF(BN$1=$D53,'Данные, контроль'!$AF52,0) -> 0 | BO51: =IF(BO$1=$D53,'Данные, контроль'!$AF52,0) -> 0 | BP51: =IF(BP$1=$D53,'Данные, контроль'!$AF52,0) -> 0 | BQ51: =IF(BQ$1=$D53,'Данные, контроль'!$AF52,0) -> 0 | ... EH51: =IF(EH$1=$D53,'Данные, контроль'!$AF52,0) -> 0
A52: 4848 | B52: 2016 | C52: компьютерных технологий и электронного обучения | D52: Государев Илья Борисович | E52: кандидат педагогических наук | F52: доцент | G52: 1 | H52: 15377 | I52: Модуль "Проектирование и разработка веб-решений " | J52: =[1]Данные!J51 -> 0 | K52: =[1]Данные!K51 -> 0 | L52: =[1]Данные!L51 -> 0 | M52: =(J52 + K52 + L52)*0.1 -> 0 | N52: =2+(0.33*W52) -> 2 | O52: =0.25*W52 -> 0 | P52: =0.25*W52 -> 0 | Q52: =[1]Данные!Q51 -> 0 | R52: =[1]Данные!R51 -> 0 | S52: =[1]Данные!S51 -> 0 | T52: =[1]Данные!T51 -> 0 | U52: =[1]Данные!U51 -> 0 | V52: =[1]Данные!V51 -> 0 | W52: =[1]Данные!W51 -> 0 | X52: =[1]Данные!X51 -> 0 | ... Z52: =[1]Данные!Z51 -> 0 | AA52: осн | BJ52: =IF(BJ$1=$D54,'Данные, контроль'!$AF53,0) -> 0 | BK52: =IF(BK$1=$D54,'Данные, контроль'!$AF53,0) -> 0 | BL52: =IF(BL$1=$D54,'Данные, контроль'!$AF53,0) -> 0 | BM52: =IF(BM$1=$D54,'Данные, контроль'!$AF53,0) -> 0 | BN52: =IF(BN$1=$D54,'Данные, контроль'!$AF53,0) -> 0 | BO52: =IF(BO$1=$D54,'Данные, контроль'!$AF53,0) -> 0 | BP52: =IF(BP$1=$D54,'Данные, контроль'!$AF53,0) -> 0 | BQ52: =IF(BQ$1=$D54,'Данные, контроль'!$AF53,0) -> 0 | ... EH52: =IF(EH$1=$D54,'Данные, контроль'!$AF53,0) -> 0
A53: 4848 | B53: 2016 | C53: компьютерных технологий и электронного обучения | D53: Государев Илья Борисович | E53: кандидат педагогических наук | F53: доцент | G53: 1 | H53: 15377 | I53: Модуль "Проектирование и разработка веб-решений ". Веб-проектирование и веб-дизайн | J53: =[1]Данные!J52 -> 17 | K53: =[1]Данные!K52 -> 17 | L53: =[1]Данные!L52 -> 20 | M53: =(J53 + K53 + L53)*0.1 -> 5.4 | N53: =2+(0.33*W53) -> 2 | O53: =0.25*W53 -> 0 | P53: =0.25*W53 -> 0 | Q53: =[1]Данные!Q52 -> 0 | R53: =[1]Данные!R52 -> 0 | S53: =[1]Данные!S52 -> 0 | T53: =[1]Данные!T52 -> 0 | U53: =[1]Данные!U52 -> 0 | V53: =[1]Данные!V52 -> 0 | W53: =[1]Данные!W52 -> 0 | X53: =[1]Данные!X52 -> 0 | ... Z53: =[1]Данные!Z52 -> 0 | AA53: осн | BJ53: =IF(BJ$1=$D55,'Данные, контроль'!$AF54,0) -> 0 | BK53: =IF(BK$1=$D55,'Данные, контроль'!$AF54,0) -> 0 | BL53: =IF(BL$1=$D55,'Данные, контроль'!$AF54,0) -> 0 | BM53: =IF(BM$1=$D55,'Данные, контроль'!$AF54,0) -> 0 | BN53: =IF(BN$1=$D55,'Данные, контроль'!$AF54,0) -> 0 | BO53: =IF(BO$1=$D55,'Данные, контроль'!$AF54,0) -> 0 | BP53: =IF(BP$1=$D55,'Данные, контроль'!$AF54,0) -> 0 | BQ53: =IF(BQ$1=$D55,'Данные, контроль'!$AF54,0) -> 0 | ... EH53: =IF(EH$1=$D55,'Данные, контроль'!$AF54,0) -> 0
...

Sheet Данные, контроль
J1: Лекции | K1: Практ. | L1: Лаб.р. | M1: конс. | N1: экз | O1: диф.зач | P1: зач | Q1: курсов.р | R1: ГЭК (защита) | S1: ГЭК (экзамен) | T1: Контроль | U1: Практики | V1: Рук-во | AI1: учебный год | AJ1: 2015/2016 | AN1: 2016/2017 | AR1: 2017/2018 | AV1: 2018/2019 | AZ1: 2019/2020 | BD1: 2020/2021 | BH1: 2021/2022 | BM1: Стандарт часов по должностям
A2: Код УП | B2: Год нагрузки | C2: Кафедра | D2: ФИО | E2: Степень | F2: Должность | G2: Ставка | H2: Код РУП | I2: Дисциплина / практика / ВКР / ГИА | J2: Часы | W2: Студ. | X2: Количество групп | Y2: Количество подгрупп | Z2: Специальность | AA2: Вид нагрузки | AB2: Стандарт часов в год | AC2: Бакалавры ИВТ / магистры КЭО | AD2: Учебный год | AE2: Сумма часов | AF2: Объём учебной нагрузки | AG2: Сумма долей работодателей | AH2: Процент работодателей от общей суммы часов | AI2: курс | AJ2: 1 | AK2: 2 | AL2: 3 | AM2: 4 | AN2: 1 | AO2: 2 | AP2: 3 | AQ2: 4 | AR2: 1 | AS2: 2 | AT2: 3 | AU2: 4 | AV2: 1 | AW2: 2 | AX2: 3 | AY2: 4 | AZ2: 1 | BA2: 2 | BB2: 3 | BC2: 4 | BD2: 1 | BE2: 2 | BF2: 3 | BG2: 4 | BH2: 1 | BI2: 2 | BJ2: 3 | BK2: 4 | BM2: Должность | BN2: Часы
AF3: =SUM('Обновлённые данные'!BJ2:EF2) -> 43.713838
A4: =[1]Данные!A3 -> 3250 | B4: =[1]Данные!B3 -> 2015 | C4: =[1]Данные!C3 -> компьютерных технологий и электронного обучения | D4: =[1]Данные!D3 -> Гончарова Светлана Викторовна | E4: =[1]Данные!E3 -> кандидат педагогических наук | F4: =[1]Данные!F3 -> доцент | G4: =[1]Данные!G3 -> 1 | H4: =[1]Данные!H3 -> 13809 | ... L4: =[1]Данные!L3 -> 102 | M4: =(J4 + K4 + L4)*0.1 -> 13.6 | N4: =2+(0.33*W4) -> 12.23 | O4: =0.25*W4 -> 7.75 | P4: =0.25*W4 -> 7.75 | Q4: =[1]Данные!Q3 -> 0 | R4: =[1]Данные!R3 -> 0 | S4: =[1]Данные!S3 -> 0 | T4: =[1]Данные!T3 -> 12 | U4: =[1]Данные!U3 -> 0 | V4: =[1]Данные!V3 -> 0 | W4: =[1]Данные!W3 -> 31 | X4: =[1]Данные!X3 -> 2 | ... AA4: =[1]Данные!AA3 -> осн | AB4: =SUMIFS($BN$4:$BN$11,$BM$4:$BM$11,F4) -> 800 | AC4: =IF(ISNUMBER(MATCH(H4,$AJ$5:$BK$5,0)),"ИВТ (бак)",IF(ISNUMBER(MATCH(H4,$AJ$6:$BK$6,0)),"КЭО (маг)","")) -> ИВТ (бак) | AD4: =IFERROR(INDEX(AJ1:BK1, MATCH(H4, AJ5:BK6, 0)), "Не найдено") -> Не найдено | AE4: =SUM(J4:V4) -> 189.33 | AF4: =AE4/AB4 -> 0.2366625 | AI4: год поступления | AJ4: 2015 | AK4: 2014 | AL4: 2013 | AM4: 2012 | AN4: 2016 | AO4: 2015 | AP4: 2014 | AQ4: 2013 | AR4: 2017 | AS4: 2016 | AT4: 2015 | AU4: 2014 | AV4: 2018 | AW4: 2017 | AX4: 2016 | AY4: 2015 | AZ4: 2019 | BA4: 2018 | BB4: 2017 | BC4: 2016 | BD4: 2020 | BE4: 2019 | BF4: 2018 | BG4: 2017 | BH4: 2021 | BI4: 2020 | BJ4: 2019 | BK4: 2018 | BM4: =[1]Данные!BG3 -> заведующий кафедрой | BN4: =[1]Данные!BH3 -> 700
A5: =[1]Данные!A4 -> 4276 | B5: =[1]Данные!B4 -> 2015 | C5: =[1]Данные!C4 -> компьютерных технологий и электронного обучения | D5: =[1]Данные!D4 -> Абрамян Геннадий Владимирович | E5: =[1]Данные!E4 -> доктор педагогических наук | F5: =[1]Данные!F4 -> профессор | G5: =[1]Данные!G4 -> 1 | H5: 13809 | I5: =[1]Данные!I4 -> Информационное обеспечение технологического образования. Применение Интернет-технологий в технологическом образовании | J5: =[1]Данные!J4 -> 18 | K5: =[1]Данные!K4 -> 0 | L5: =[1]Данные!L4 -> 54 | M5: =(J5 + K5 + L5)*0.1 -> 7.2 | N5: =2+(0.33*W5) -> 2 | O5: =0.25*W5 -> 0 | P5: =0.25*W5 -> 0 | Q5: =[1]Данные!Q4 -> 0 | R5: =[1]Данные!R4 -> 0 | S5: =[1]Данные!S4 -> 0 | T5: =[1]Данные!T4 -> 21 | U5: =[1]Данные!U4 -> 0 | V5: =[1]Данные!V4 -> 0 | W5: =[1]Данные!W4 -> 0 | X5: =[1]Данные!X4 -> 0 | ... AA5: =[1]Данные!AA4 -> осн | AB5: =SUMIFS($BN$4:$BN$11,$BM$4:$BM$11,F5) -> 750 | AC5: =IF(ISNUMBER(MATCH(H5,$AJ$5:$BK$5,0)),"ИВТ (бак)",IF(ISNUMBER(MATCH(H5,$AJ$6:$BK$6,0)),"КЭО (маг)","")) -> ИВТ (бак) | AD5: =IFERROR(INDEX(AJ2:BK2, MATCH(H5, AJ6:BK7, 0), 1), "Не найдено") -> Не найдено | AE5: =SUM(J5:V5) -> 102.2 | AF5: =AE5/AB5 -> 0.13626667 | AI5: Бакалавры (ИВТ) | AJ5: =[1]Данные!AD4 -> 14014 | AK5: =[1]Данные!AE4 -> 52346 | AL5: =[1]Данные!AF4 -> 8775 | AM5: =[1]Данные!AG4 -> 37233 | AN5: 13809 | AO5: =[1]Данные!AI4 -> 13809 | AP5: =[1]Данные!AJ4 -> 25386 | AQ5: =[1]Данные!AK4 -> 27453 | AR5: =[1]Данные!AL4 -> 16591 | AS5: =[1]Данные!AM4 -> 16002 | AT5: =[1]Данные!AN4 -> 16003 | AU5: =[1]Данные!AO4 -> 16457 | AV5: =[1]Данные!AP4 -> 17043 | ... BK5: =[1]Данные!BE4 -> 4 курс 2018 год/пост | BM5: =[1]Данные!BG4 -> профессор | BN5: =[1]Данные!BH4 -> 750
A6: =[1]Данные!A5 -> 4276 | B6: =[1]Данные!B5 -> 2015 | C6: =[1]Данные!C5 -> компьютерных технологий и электронного обучения | D6: =[1]Данные!D5 -> Авксентьева Елена Юрьевна | E6: =[1]Данные!E5 -> кандидат педагогических наук | F6: =[1]Данные!F5 -> доцент | G6: =[1]Данные!G5 -> 1 | H6: =[1]Данные!H5 -> 13818 | ... L6: =[1]Данные!L5 -> 0 | M6: =(J6 + K6 + L6)*0.1 -> 0 | N6: =2+(0.33*W6) -> 6.29 | O6: =0.25*W6 -> 3.25 | P6: =0.25*W6 -> 3.25 | Q6: =[1]Данные!Q5 -> 0 | R6: =[1]Данные!R5 -> 0 | S6: =[1]Данные!S5 -> 0 | T6: =[1]Данные!T5 -> 15 | U6: =[1]Данные!U5 -> 0 | V6: =[1]Данные!V5 -> 0 | W6: =[1]Данные!W5 -> 13 | X6: =[1]Данные!X5 -> 2 | ... AA6: =[1]Данные!AA5 -> осн | AB6: =SUMIFS($BN$4:$BN$11,$BM$4:$BM$11,F6) -> 800 | AC6: =IF(ISNUMBER(MATCH(H6,$AJ$5:$BK$5,0)),"ИВТ (бак)",IF(ISNUMBER(MATCH(H6,$AJ$6:$BK$6,0)),"КЭО (маг)","")) | AD6: =IFERROR(INDEX(AJ4:BK4, MATCH(H6, AJ7:BK8, 0), 1), "Не найдено") -> Не найдено | AE6: =SUM(J6:V6) -> 27.79 | AF6: =AE6/AB6 -> 0.0347375 | AI6: Магистры (КЭО) | AJ6: =[1]Данные!AD5 -> 86354 | AK6: =[1]Данные!AE5 -> 80249 | AL6: =[1]Данные!AF5 -> 1 | AM6: =[1]Данные!AG5 -> 1 | AN6: =[1]Данные!AH5 -> 19404 | AO6: =[1]Данные!AI5 -> 19403 | AP6: =[1]Данные!AJ5 -> 1 | AQ6: =[1]Данные!AK5 -> 1 | ... BK6: =[1]Данные!BE5 -> 0 | BM6: =[1]Данные!BG5 -> доцент | BN6: =[1]Данные!BH5 -> 800
A7: =[1]Данные!A6 -> 4276 | B7: =[1]Данные!B6 -> 2015 | C7: =[1]Данные!C6 -> компьютерных технологий и электронного обучения | D7: =[1]Данные!D6 -> Гончарова Светлана Викторовна | E7: =[1]Данные!E6 -> кандидат педагогических наук | F7: =[1]Данные!F6 -> доцент | G7: =[1]Данные!G6 -> 1 | H7: =[1]Данные!H6 -> 13818 | ... L7: =[1]Данные!L6 -> 0 | M7: =(J7 + K7 + L7)*0.1 -> 4.1 | N7: =2+(0.33*W7) -> 6.29 | O7: =0.25*W7 -> 3.25 | P7: =0.25*W7 -> 3.25 | Q7: =[1]Данные!Q6 -> 0 | R7: =[1]Данные!R6 -> 0 | S7: =[1]Данные!S6 -> 0 | T7: =[1]Данные!T6 -> 3 | U7: =[1]Данные!U6 -> 0 | V7: =[1]Данные!V6 -> 0 | W7: =[1]Данные!W6 -> 13 | X7: =[1]Данные!X6 -> 2 | ... AA7: =[1]Данные!AA6 -> осн | AB7: =SUMIFS($BN$4:$BN$11,$BM$4:$BM$11,F7) -> 800 | AC7: =IF(ISNUMBER(MATCH(H7,$AJ$5:$BK$5,0)),"ИВТ (бак)",IF(ISNUMBER(MATCH(H7,$AJ$6:$BK$6,0)),"КЭО (маг)","")) | AD7: =IFERROR(INDEX(AJ5:BK5, MATCH(H7, AJ8:BK9, 0), 1), "Не найдено") -> Не найдено | AE7: =SUM(J7:V7) -> 60.89 | AF7: =AE7/AB7 -> 0.0761125 | BM7: =[1]Данные!BG6 -> старший преподаватель | BN7: =[1]Данные!BH6 -> 850
A8: =[1]Данные!A7 -> 4276 | B8: =[1]Данные!B7 -> 2015 | C8: =[1]Данные!C7 -> компьютерных технологий и электронного обучения | D8: =[1]Данные!D7 -> Ильина Татьяна Сергеевна | E8: =[1]Данные!E7 -> нет | F8: =[1]Данные!F7 -> старший преподаватель | G8: =[1]Данные!G7 -> 1 | H8: =[1]Данные!H7 -> 13818 | ... L8: =[1]Данные!L7 -> 0 | M8: =(J8 + K8 + L8)*0.1 -> 6.4 | N8: =2+(0.33*W8) -> 2 | O8: =0.25*W8 -> 0 | P8: =0.25*W8 -> 0 | Q8: =[1]Данные!Q7 -> 0 | R8: =[1]Данные!R7 -> 0 | S8: =[1]Данные!S7 -> 0 | T8: =[1]Данные!T7 -> 3 | U8: =[1]Данные!U7 -> 0 | V8: =[1]Данные!V7 -> 0 | W8: =[1]Данные!W7 -> 0 | X8: =[1]Данные!X7 -> 0 | ... AA8: =[1]Данные!AA7 -> осн | AB8: =SUMIFS($BN$4:$BN$11,$BM$4:$BM$11,F8) -> 850 | AC8: =IF(ISNUMBER(MATCH(H8,$AJ$5:$BK$5,0)),"ИВТ (бак)",IF(ISNUMBER(MATCH(H8,$AJ$6:$BK$6,0)),"КЭО (маг)","")) | AD8: =IFERROR(INDEX(AJ6:BK6, MATCH(H8, AJ9:BK10, 0), 1), "Не найдено") -> Не найдено | AE8: =SUM(J8:V8) -> 75.4 | AF8: =AE8/AB8 -> 0.088705882 | BM8: =[1]Данные!BG7 -> ассистент | BN8: =[1]Данные!BH7 -> 900
A9: =[1]Данные!A8 -> 4276 | B9: =[1]Данные!B8 -> 2016 | C9: =[1]Данные!C8 -> компьютерных технологий и электронного обучения | D9: =[1]Данные!D8 -> Готская Ирина Борисовна | E9: =[1]Данные!E8 -> доктор педагогических наук | F9: =[1]Данные!F8 -> профессор | G9: =[1]Данные!G8 -> 1 | H9: =[1]Данные!H8 -> 14784 | ... L9: =[1]Данные!L8 -> 120 | M9: =(J9 + K9 + L9)*0.1 -> 15.2 | N9: =2+(0.33*W9) -> 2 | O9: =0.25*W9 -> 0 | P9: =0.25*W9 -> 0 | Q9: =[1]Данные!Q8 -> 0 | R9: =[1]Данные!R8 -> 0 | S9: =[1]Данные!S8 -> 0 | T9: =[1]Данные!T8 -> 21 | U9: =[1]Данные!U8 -> 0 | V9: =[1]Данные!V8 -> 0 | W9: =[1]Данные!W8 -> 0 | X9: =[1]Данные!X8 -> 0 | ... AA9: =[1]Данные!AA8 -> осн | AB9: =SUMIFS($BN$4:$BN$11,$BM$4:$BM$11,F9) -> 750 | AC9: =IF(ISNUMBER(MATCH(H9,$AJ$5:$BK$5,0)),"ИВТ (бак)",IF(ISNUMBER(MATCH(H9,$AJ$6:$BK$6,0)),"КЭО (маг)","")) | AD9: =IFERROR(INDEX(AJ7:BK7, MATCH(H9, AJ10:BK11, 0), 1), "Не найдено") -> Не найдено | AE9: =SUM(J9:V9) -> 190.2 | AF9: =AE9/AB9 -> 0.2536 | AI9: учебный год | AJ9: 2015/2016 | AN9: 2016/2017 | AR9: 2017/2018 | AV9: 2018/2019 | AZ9: 2019/2020 | BD9: 2020/2021 | BH9: 2021/2022 | BM9: =[1]Данные!BG8 -> эксперт-программист | BN9: =[1]Данные!BH8 -> 900
